Workbook

Sheet Cover
B2: Apple
C11: Apple Inc. – DCF Valuation & Analysis
C13: Table of Contents | H13: Model Checks
C15: Summary | H15: Incorrect Date Set for Valuation? | M15: =Inputs!$F$107 -> 0
C16: Inputs | H16: Incorrect Date Set for First Cash Flow? | M16: =Inputs!$F$108 -> 0
C17: Model | H17: Terminal Growth Rate Greater Than or Equal To WACC? | M17: =Inputs!$F$119 -> 0
C18: DCF | H18: Model Exceeding Operational Capacity? | M18: =IF(SUM(Model!$F$179:$N$179)>0,1,0) -> 0
H19: Unused Tax Losses Remaining? (Levered Schedule) | M19: =Model!$D$366 -> 0
H20: Unused Tax Losses Remaining? (Unlevered Schedule) | M20: =Model!$D$408 -> 0
H21: Two UFCF Methods Different? | M21: =IF(SUM(Model!$AI$427:$AN$427)>0,1,0) -> 0

Sheet Summary_Sheet
C1: Apple
B3: Apple Inc. – DCF Valuation & Analysis
C5: This model provides a 5-year integrated forecast (2026–2030) for Apple Inc.
C6: It calculates intrinsic value using both Perpetuity Growth and Exit Multiple methods,
C7: with interactive sensitivity analysis hosted in Power BI.
C9: All figures in USD millions unless stated
B12: Current Stock Price | F12: =Inputs!F115 -> 258.87
B13: Implied Share Price (Perpetuity) | F13: =DCF!M82 -> 134.64814
B14: Implied Share Price (Exit Multiple) | F14: =DCF!M129 -> 207.81543
B15: WACC | F15: =Inputs!L76 -> 0.08564409
B16: Terminal Growth Rate | F16: =Inputs!F116 -> 0.025
B17: Terminal EBITDA Multiple | F17: =Inputs!F117 -> 22
B18: Blended Upside / (Downside) | F18: =AVERAGE(((F13-F12)/F12),(F14-F12)/F12) -> -0.33854141
D23: =HYPERLINK(LEFT(CELL("filename",A1),FIND("[",CELL("filename",A1))-1)&"Apple_dashboard.pbix","▶ View Power BI Dashboard") -> ▶ View Power BI Dashboard
B27: Summary
C29: Year | D29: UFCF | E29: Net Cash | F29: Shares Outstanding | I29: Year | J29: UFCF | K29: EBITDA | L29: Net Cash | M29: Shares Outstanding
C30: 2026 | D30: =DCF!I21 -> 112360.89 | E30: =-Inputs!$L$107 -> 54286 | F30: =Inputs!$F$114 -> 14776 | I30: 2026 | J30: =DCF!I31 -> 112360.89 | K30: =DCF!$N$98 -> 177027.97 | L30: =-Inputs!$L$107 -> 54286 | M30: =Inputs!$F$114 -> 14776
C31: 2027 | D31: =DCF!J21 -> 121173.02 | E31: =-Inputs!$L$107 -> 54286 | F31: =Inputs!$F$114 -> 14776 | I31: 2027 | J31: =DCF!J31 -> 121173.02 | K31: =DCF!$N$98 -> 177027.97 | L31: =-Inputs!$L$107 -> 54286 | M31: =Inputs!$F$114 -> 14776
C32: 2028 | D32: =DCF!K21 -> 125735.19 | E32: =-Inputs!$L$107 -> 54286 | F32: =Inputs!$F$114 -> 14776 | I32: 2028 | J32: =DCF!K31 -> 125735.19 | K32: =DCF!$N$98 -> 177027.97 | L32: =-Inputs!$L$107 -> 54286 | M32: =Inputs!$F$114 -> 14776
C33: 2029 | D33: =DCF!L21 -> 128851.36 | E33: =-Inputs!$L$107 -> 54286 | F33: =Inputs!$F$114 -> 14776 | I33: 2029 | J33: =DCF!L31 -> 128851.36 | K33: =DCF!$N$98 -> 177027.97 | L33: =-Inputs!$L$107 -> 54286 | M33: =Inputs!$F$114 -> 14776
C34: 2030 | D34: =DCF!M21 -> 131822.8 | E34: =-Inputs!$L$107 -> 54286 | F34: =Inputs!$F$114 -> 14776 | I34: 2030 | J34: =DCF!M31 -> 131822.8 | K34: =DCF!$N$98 -> 177027.97 | L34: =-Inputs!$L$107 -> 54286 | M34: =Inputs!$F$114 -> 14776
C35: term | D35: =DCF!N21 -> 130172.3 | E35: =-Inputs!$L$107 -> 54286 | F35: =Inputs!$F$114 -> 14776 | I35: term | J35: =DCF!N31 -> 130172.3 | K35: =DCF!$N$98 -> 177027.97 | L35: =-Inputs!$L$107 -> 54286 | M35: =Inputs!$F$114 -> 14776
B38: This integrated valuation hub bridges a 5-year 3-statement forecast with dynamic DCF modeling.
B39: The analysis indicates a significant valuation gap, with the current market price trading at a 33.9% premium to the fundamental intrinsic value.
B40: Interactive sensitivity analysis of WACC and Terminal Growth is available via the Power BI link above.

Sheet Inputs
B1: Apple
B3: Drivers
B5: All figures in USD millions unless stated | G5: =$F$106 -> 2026 | H5: =G5+1 -> 2027 | I5: =H5+1 -> 2028 | J5: =I5+1 -> 2029 | K5: =J5+1 -> 2030 | L5: Term
B7: Driver Switch | D7: 2
B10: Sales Volume Growth | G10: {=INDEX(G12:G14,$D$7)} -> 0.043 | H10: {=INDEX(H12:H14,$D$7)} -> 0.032 | I10: {=INDEX(I12:I14,$D$7)} -> 0.017 | J10: {=INDEX(J12:J14,$D$7)} -> 0.016 | K10: {=INDEX(K12:K14,$D$7)} -> 0.016 | L10: {=INDEX(L12:L14,$D$7)} -> 0.01
B12: Best Case | G12: 0.065 | H12: 0.055 | I12: 0.04 | J12: 0.035 | K12: 0.035 | L12: 0.03
B13: Base Case | G13: 0.043 | H13: 0.032 | I13: 0.017 | J13: 0.016 | K13: 0.016 | L13: 0.01
B14: Worst Case | G14: 0.01 | H14: 0 | I14: -0.015 | J14: -0.02 | K14: -0.02 | L14: 0
B17: Pricing Increases | G17: {=INDEX(G19:G21,$D$7)} -> 0.025 | H17: {=INDEX(H19:H21,$D$7)} -> 0.015 | I17: {=INDEX(I19:I21,$D$7)} -> 0.015 | J17: {=INDEX(J19:J21,$D$7)} -> 0.01 | K17: {=INDEX(K19:K21,$D$7)} -> 0.01 | L17: {=INDEX(L19:L21,$D$7)} -> 0.015
B19: =$B$12 -> Best Case | G19: 0.035 | H19: 0.025 | I19: 0.02 | J19: 0.02 | K19: 0.02 | L19: 0.02
B20: =$B$13 -> Base Case | G20: 0.025 | H20: 0.015 | I20: 0.015 | J20: 0.01 | K20: 0.01 | L20: 0.015
B21: =$B$14 -> Worst Case | G21: -0.01 | H21: 0 | I21: 0 | J21: -0.005 | K21: -0.01 | L21: 0.005
B24: Capital Expenditure | G24: {=INDEX(G26:G28,$D$7)} -> 14500 | H24: {=INDEX(H26:H28,$D$7)} -> 15200 | I24: {=INDEX(I26:I28,$D$7)} -> 15800 | J24: {=INDEX(J26:J28,$D$7)} -> 16500 | K24: {=INDEX(K26:K28,$D$7)} -> 17200 | L24: {=INDEX(L26:L28,$D$7)} -> 18500
B26: =$B$12 -> Best Case | G26: 16000 | H26: 17500 | I26: 18500 | J26: 20000 | K26: 22000 | L26: 23000
B27: =$B$13 -> Base Case | G27: 14500 | H27: 15200 | I27: 15800 | J27: 16500 | K27: 17200 | L27: 18500
B28: =$B$14 -> Worst Case | G28: 13500 | H28: 14000 | I28: 14500 | J28: 15000 | K28: 15500 | L28: 16000
B31: Inflation Rate | G31: 0.024 | H31: 0.025 | I31: 0.023 | J31: 0.022 | K31: 0.021 | L31: 0.02
B36: Weighted Average Cost of Capital
B38: All figures in USD millions unless stated
H40: Average | I40: Debt/ | J40: Debt/ | K40: Levered | L40: Unlevered
B41: Name | D41: Region | F41: Debt | G41: Equity | H41: Tax Rate 1 | I41: Equity | J41: Capital | K41: Beta 2 | L41: Beta 3
B43: Microsoft (MSFT) | D43: Europe | F43: 35430 | G43: 3010000 | H43: 0.186 | I43: =F43/G43 -> 0.011770764 | J43: =F43/(F43+G43) -> 0.011633825 | K43: 0.92 | L43: =K43/(1+(1-H43)*I43) -> 0.91126877
B44: Alphabet (GOOGL) | D44: Europe | F44: 46550 | G44: 3680000 | H44: 0.159 | I44: =F44/G44 -> 0.012649457 | J44: =F44/(F44+G44) -> 0.012491447 | K44: 1.08 | L44: =K44/(1+(1-H44)*I44) -> 1.0686317
B45: Amazon (AMZN) | D45: Europe | F45: 67200 | G45: 2300000 | H45: 0.19 | I45: =F45/G45 -> 0.029217391 | J45: =F45/(F45+G45) -> 0.028387969 | K45: 1.15 | L45: =K45/(1+(1-H45)*I45) -> 1.1234132
B46: Samsung (SMSN) | D46: Europe | F46: 13800 | G46: 580000 | H46: 0.254 | I46: =F46/G46 -> 0.023793103 | J46: =F46/(F46+G46) -> 0.023240148 | K46: 1.25 | L46: =K46/(1+(1-H46)*I46) -> 1.2281999
B47: Sony (SONY) | D47: Europe | F47: 24700 | G47: 124620 | H47: 0.235 | I47: =F47/G47 -> 0.19820254 | J47: =F47/(F47+G47) -> 0.16541656 | K47: 1.2 | L47: =K47/(1+(1-H47)*I47) -> 1.0420059
G49: Average | H49: =AVERAGE(H43:H47) -> 0.2048 | I49: =AVERAGE(I43:I47) -> 0.05512665 | J49: =AVERAGE(J43:J47) -> 0.048233989 | K49: =AVERAGE(K43:K47) -> 1.12 | L49: =AVERAGE(L43:L47) -> 1.0747039
G50: Median | H50: =MEDIAN(H43:H47) -> 0.19 | I50: =MEDIAN(I43:I47) -> 0.023793103 | J50: =MEDIAN(J43:J47) -> 0.023240148 | K50: =MEDIAN(K43:K47) -> 1.15 | L50: =MEDIAN(L43:L47) -> 1.0686317
B53: Risk Premium for Equity | H53: Cost of Equity
B55: Market Risk Premium | F55: 0.04 | H55: Risk Free Rate | L55: 0.043
B56: Average Unlevered Beta | F56: =$L$49 -> 1.0747039 | H56: Equity Risk Premium | L56: =F58 -> 0.044077041
B57: Levered Beta 4 | F57: =F56*(1+(1-L65)*F69) -> 1.101926 | H57: Country Risk Premium | L57: 0
B58: Equity Risk Premium | F58: =F55*F57 -> 0.044077041 | H58: Cost of Equity | L58: =SUM(L55:L57) -> 0.087077041
B62: Capital Structure | H62: Cost of Debt
E64: Current | F64: Target | H64: Pre-Tax Cost of Debt | L64: 0.048
B65: Total Debt | D65: 106620 | E65: =D65/$D$67 -> 0.031764096 | F65: 0.03 | H65: Tax Rate | L65: 0.181
B66: Market Capitalization | D66: 3250000 | E66: =D66/$D$67 -> 0.9682359 | F66: =1-F65 -> 0.97 | H66: After-Tax Cost of Debt | L66: =L64*(1-L65) -> 0.039312
B67: Total Capitalization | D67: =SUM(D65:D66) -> 3356620 | E67: =SUM(E65:E66) -> 1 | F67: =SUM(F65:F66) -> 1
B69: Debt / Equity | E69: =E65/E66 -> 0.032806154 | F69: =F65/F66 -> 0.030927835 | H69: Weighted Average Cost of Capital
K71: Weight | L71: Cost
...

Sheet Model
B1: Apple
B3: Income Statement
B5: All figures in USD millions unless stated | F5: =F$141 -> 2023 | G5: =G$141 -> 2024 | H5: =H$141 -> 2025 | I5: =I$141 -> 2026 | J5: =J$141 -> 2027 | K5: =K$141 -> 2028 | L5: =L$141 -> 2029 | M5: =M$141 -> 2030 | N5: =N$141 -> Term
B6: =$B$142 -> Model Running: Base Case Drivers
B8: Inflation | F8: =F189 -> 0.034 | G8: =G189 -> 0.024 | H8: =H189 -> 0.023 | I8: =I189 -> 0.024 | J8: =J189 -> 0.025 | K8: =K189 -> 0.023 | L8: =L189 -> 0.022 | M8: =M189 -> 0.021 | N8: =N189 -> 0.02
B11: Tax Rate | C11: =Inputs!$L$65 -> 0.181
B13: Revenue | F13: 383285 | G13: 391035 | H13: 416161 | I13: =I176 -> 444907.41 | J13: =J176 -> 466031.62 | K13: =K176 -> 481063.47 | L13: =L176 -> 493648.09 | M13: =M176 -> 506561.92 | N13: =N176 -> 519301.95
B14: COGS | F14: -214137 | G14: -210352 | H14: -220960 | I14: =I225*-1 -> -235287.99 | J14: =J225*-1 -> -248350.18 | K14: =K225*-1 -> -258089.2 | L14: =L225*-1 -> -267706.47 | M14: =M225*-1 -> -277414.7 | N14: =N225*-1 -> -285609.75
B15: Gross Profit | F15: =SUM(F13:F14) -> 169148 | G15: =SUM(G13:G14) -> 180683 | H15: =SUM(H13:H14) -> 195201 | I15: =SUM(I13:I14) -> 209619.42 | J15: =SUM(J13:J14) -> 217681.44 | K15: =SUM(K13:K14) -> 222974.27 | L15: =SUM(L13:L14) -> 225941.61 | M15: =SUM(M13:M14) -> 229147.22 | N15: =SUM(N13:N14) -> 233692.2
B18: SG&A | F18: -24932 | G18: -26097 | H18: -27601 | I18: =H18*(1+I$8) -> -28263.424 | J18: =I18*(1+J$8) -> -28970.01 | K18: =J18*(1+K$8) -> -29636.32 | L18: =K18*(1+L$8) -> -30288.319 | M18: =L18*(1+M$8) -> -30924.374 | N18: =M18*(1+N$8) -> -31542.861
B19: R&D | F19: -29915 | G19: -31370 | H19: -34550 | I19: =-I13*Inputs!$L$116 -> -37817.13 | J19: =-J13*Inputs!$L$116 -> -39612.687 | K19: =-K13*Inputs!$L$116 -> -40890.395 | L19: =-L13*Inputs!$L$116 -> -41960.087 | M19: =-M13*Inputs!$L$116 -> -43057.763 | N19: =-N13*Inputs!$L$116 -> -44140.666
B20: Other | F20: 0 | G20: 0 | H20: 0 | I20: =-I13*Inputs!$L$117 -> 444.90741 | J20: =-J13*Inputs!$L$117 -> 466.03162 | K20: =-K13*Inputs!$L$117 -> 481.06347 | L20: =-L13*Inputs!$L$117 -> 493.64809 | M20: =-M13*Inputs!$L$117 -> 506.56192 | N20: =-N13*Inputs!$L$117 -> 519.30195
B22: Depreciation | F22: -11519 | G22: -11445 | H22: -11698 | I22: =-I319 -> -11002.514 | J22: =-J319 -> -13123.943 | K22: =-K319 -> -15338.229 | L22: =-L319 -> -17645.371 | M22: =-M319 -> -20052.514 | N22: =-Inputs!L24 -> -18500
B23: EBIT | F23: =SUM(F15:F20) -> 114301 | G23: =SUM(G15:G20) -> 123216 | H23: =SUM(H15:H20) -> 133050 | I23: =SUM(I15:I20) -> 143983.77 | J23: =SUM(J15:J20) -> 149564.77 | K23: =SUM(K15:K20) -> 152928.62 | L23: =SUM(L15:L20) -> 154186.85 | M23: =SUM(M15:M20) -> 155671.64 | N23: =SUM(N15:N20) -> 158527.97
B26: Interest Income | F26: 3750 | G26: 3921 | H26: 3744 | I26: =I454 -> 1518.6989 | J26: =J454 -> 1867.4504 | K26: =K454 -> 2560.0993 | L26: =L454 -> 3412.518 | M26: =M454 -> 4484.6858 | N26: =M26*(1+Inputs!$F$116) -> 4596.8029
B27: Interest Expense | F27: -3933 | G27: -3803 | H27: -3767 | I27: =-I500 -> -3421.834 | J27: =-J500 -> -3020.384 | K27: =-K500 -> -2653.159 | L27: =-L500 -> -2250.784 | M27: =-M500 -> -1885.409 | N27: =M27*(1+Inputs!$F$116) -> -1932.5442
B28: Other Income/(Expense) | F28: -382 | G28: 151 | H28: -298 | I28: -200 | J28: -200 | K28: -200 | L28: -200 | M28: -200 | N28: 0
B29: EBT | F29: =SUM(F23:F28) -> 113736 | G29: =SUM(G23:G28) -> 123485 | H29: =SUM(H23:H28) -> 132729 | I29: =SUM(I23:I28) -> 141880.64 | J29: =SUM(J23:J28) -> 148211.84 | K29: =SUM(K23:K28) -> 152635.56 | L29: =SUM(L23:L28) -> 155148.59 | M29: =SUM(M23:M28) -> 158070.92 | N29: =SUM(N23:N28) -> 161192.23
B31: Current Tax | F31: -17589 | G31: -32864 | H31: -18252 | I31: =-I389 -> -25282.104 | J31: =-J389 -> -26351.256 | K31: =-K389 -> -27071.792 | L31: =-L389 -> -27443.132 | M31: =-M389 -> -27884.935 | N31: =-C11*N29 -> -29175.794
B32: Deferred Tax | F32: 848 | G32: 3115 | H32: -2467 | I32: =-I390 -> -398.29102 | J32: =-J390 -> -475.08673 | K32: =-K390 -> -555.24387 | L32: =-L390 -> -638.76245 | M32: =-M390 -> -725.90102 | N32: 0
B33: Total Tax | F33: =SUM(F31:F32) -> -16741 | G33: =SUM(G31:G32) -> -29749 | H33: =SUM(H31:H32) -> -20719 | I33: =SUM(I31:I32) -> -25680.395 | J33: =SUM(J31:J32) -> -26826.343 | K33: =SUM(K31:K32) -> -27627.036 | L33: =SUM(L31:L32) -> -28081.894 | M33: =SUM(M31:M32) -> -28610.836 | N33: =SUM(N31:N32) -> -29175.794
B35: Net Income | F35: =F29+F33 -> 96995 | G35: =G29+G33 -> 93736 | H35: =H29+H33 -> 112010 | I35: =I29+I33 -> 116200.24 | J35: =J29+J33 -> 121385.5 | K35: =K29+K33 -> 125008.52 | L35: =L29+L33 -> 127066.69 | M35: =M29+M33 -> 129460.08 | N35: =N29+N33 -> 132016.44
B39: Cash Flow Statement
B41: All figures in USD millions unless stated | F41: =F$141 -> 2023 | G41: =G$141 -> 2024 | H41: =H$141 -> 2025 | I41: =I$141 -> 2026 | J41: =J$141 -> 2027 | K41: =K$141 -> 2028 | L41: =L$141 -> 2029 | M41: =M$141 -> 2030
B42: =$B$142 -> Model Running: Base Case Drivers
B45: CASH FROM OPERATING
B46: Net Income | F46: =F35 -> 96995 | G46: =G35 -> 93736 | H46: =H35 -> 112010 | I46: =I35 -> 116200.24 | J46: =J35 -> 121385.5 | K46: =K35 -> 125008.52 | L46: =L35 -> 127066.69 | M46: =M35 -> 129460.08
B47: Deferred Taxes | F47: =-F32 -> -848 | G47: =-G32 -> -3115 | H47: =-H32 -> 2467 | I47: =-I32 -> 398.29102 | J47: =-J32 -> 475.08673 | K47: =-K32 -> 555.24387 | L47: =-L32 -> 638.76245 | M47: =-M32 -> 725.90102
B48: Depreciation | F48: =-F22 -> 11519 | G48: =-G22 -> 11445 | H48: =-H22 -> 11698 | I48: =-I22 -> 11002.514 | J48: =-J22 -> 13123.943 | K48: =-K22 -> 15338.229 | L48: =-L22 -> 17645.371 | M48: =-M22 -> 20052.514
B49: Cash From Accounts Receivable | F49: -1688 | G49: -3788 | H49: -6682 | I49: =I266 -> -2885.3545 | J49: =J266 -> -2025.6086 | K49: =K266 -> -1441.4103 | L49: =L266 -> -1206.7444 | M49: =M266 -> -1238.3128
B50: Cash From Vendor Non-Trade Receivables | F50: -6245 | G50: -1356 | H50: -347 | I50: =I267 -> -3387.7325 | J50: =J267 -> -1736.2359 | K50: =K267 -> -1235.4945 | L50: =L267 -> -1034.3523 | M50: =M267 -> -1061.411
B51: Cash From Inventory | F51: -1618 | G51: -1046 | H51: 1400 | I51: =I268 -> -728.24643 | J51: =J268 -> -357.86805 | K51: =K268 -> -266.82241 | L51: =L268 -> -263.48704 | M51: =M268 -> -265.97887
B52: Cash From Other Current Assets | F52: 6528 | G52: =G269 -> 408 | H52: =H269 -> -298 | I52: =I269 -> -350.04 | J52: =J269 -> -373.376 | K52: =K269 -> -352.09357 | L52: =L269 -> -344.53121 | M52: =M269 -> -336.10586
B53: Cash From Other Non-Current Assets | F53: -10330 | G53: =G270 -> -10076 | H53: =H270 -> -8893 | I53: =I270 -> -2009.448 | J53: =J270 -> -2143.4112 | K53: =K270 -> -2021.2368 | L53: =L270 -> -1977.8241 | M53: =M270 -> -1929.4573
B54: Cash From Other Current Liabilities | F54: -2016 | G54: =G271 -> 19475 | H54: =H271 -> -11917 | I54: =I271 -> 1593.288 | J54: =J271 -> 1699.5072 | K54: =K271 -> 1602.6353 | L54: =L271 -> 1568.2135 | M54: =M271 -> 1529.8635
B55: Cash From Other Non-Current Liabilities | F55: 706 | G55: =G272 -> -845 | H55: =H272 -> -6806 | I55: =I272 -> 1033.08 | J55: =J272 -> 1101.952 | K55: =K272 -> 1039.1407 | L55: =L272 -> 1016.8218 | M55: =M272 -> 991.95589
B56: Cash From Accounts Payable | F56: -1889 | G56: 6020 | H56: 902 | I56: =I273 -> 4271.834 | J56: =J273 -> 4115.4825 | K56: =K273 -> 3068.4577 | L56: =L273 -> 3030.1009 | M56: =M273 -> 3058.757
B57: Cash from Deferred Revenue | F57: -291 | G57: =G111-F111 -> 188 | H57: =H111-G111 -> 806 | I57: =I111-H111 -> 288.05564 | J57: =J111-I111 -> 443.60828 | K57: =K111-J111 -> 315.66884 | L57: =L111-K111 -> 264.27703 | M57: =M111-L111 -> 271.19051
B58: Share-Based Compensation | F58: 10833 | G58: 11688 | H58: 12863 | I58: =I515 -> 15068.427 | J58: =J515 -> 15846.644 | K58: =K515 -> 16430.796 | L58: =L515 -> 16997.744 | M58: =M515 -> 17569.842
B59: Other Historical Adjustments | F59: 8887 | G59: -4480 | H59: 4279 | I59: 0 | J59: 0 | K59: 0 | L59: 0 | M59: 0
...

Sheet DCF
B1: Apple
B3: Unlevered Free Cash Flow Schedule
B5: All figures in USD millions unless stated | I5: =Model!I5:N5 -> 2026 | J5: =Model!J5:O5 -> 2027 | K5: =Model!K5:P5 -> 2028 | L5: =Model!L5:Q5 -> 2029 | M5: =Model!M5:R5 -> 2030 | N5: =Model!N5:S5 -> Term
B6: =Model!$B$6 -> Model Running: Base Case Drivers
B8: TAX SHIELD FROM INTEREST | F8: Line Item | G8: Term
B9: Current Taxes (Unlevered) | F9: EBIT | G9: =Model!N23 -> 158527.97 | I9: =Model!I431 -> 25662.771 | J9: =Model!J431 -> 26596.137 | K9: =Model!K431 -> 27124.836 | L9: =Model!L431 -> 27269.058 | M9: =Model!M431 -> 27450.666 | N9: =G9*$G$11 -> 28693.563
B10: Current Taxes (Levered) | F10: EBT | G10: =Model!N29 -> 161192.23 | I10: =Model!I389 -> 25282.104 | J10: =Model!J389 -> 26351.256 | K10: =Model!K389 -> 27071.792 | L10: =Model!L389 -> 27443.132 | M10: =Model!M389 -> 27884.935 | N10: =G10*$G$11 -> 29175.794
B11: Total Tax Shield | F11: Tax Rate | G11: =Model!$C$11 -> 0.181 | I11: =I9-I10 -> 380.66745 | J11: =J9-J10 -> 244.88098 | K11: =K9-K10 -> 53.043807 | L11: =L9-L10 -> -174.07385 | M11: =M9-M10 -> -434.2691 | N11: =N9-N10 -> -482.23083
B16: EBITDA METHOD
B17: EBITDA | I17: =Model!I23+(-Model!I22) -> 154986.28 | J17: =Model!J23+(-Model!J22) -> 162688.71 | K17: =Model!K23+(-Model!K22) -> 168266.85 | L17: =Model!L23+(-Model!L22) -> 171832.23 | M17: =Model!M23+(-Model!M22) -> 175724.16 | N17: =Model!N23+(-Model!N22) -> 177027.97
B18: Current Taxes | I18: =-I9 -> -25662.771 | J18: =-J9 -> -26596.137 | K18: =-K9 -> -27124.836 | L18: =-L9 -> -27269.058 | M18: =-M9 -> -27450.666 | N18: =-N9 -> -28693.563
B19: Capital Expenditure | I19: =-Inputs!G24 -> -14500 | J19: =-Inputs!H24 -> -15200 | K19: =-Inputs!I24 -> -15800 | L19: =-Inputs!J24 -> -16500 | M19: =-Inputs!K24 -> -17200 | N19: =-Inputs!L24 -> -18500
B20: Change in Working Capital | I20: =Model!I274 -> -2462.6195 | J20: =Model!J274 -> 280.44197 | K20: =Model!K274 -> 393.17628 | L20: =Model!L274 -> 788.19707 | M20: =Model!M274 -> 749.31049 | N20: =Model!N274 -> 337.88612
B21: Unlevered Free Cash Flow | I21: =SUM(I17:I20) -> 112360.89 | J21: =SUM(J17:J20) -> 121173.02 | K21: =SUM(K17:K20) -> 125735.19 | L21: =SUM(L17:L20) -> 128851.36 | M21: =SUM(M17:M20) -> 131822.8 | N21: =SUM(N17:N20) -> 130172.3
B24: NET INCOME METHOD
B25: Net Income | I25: =Model!I35 -> 116200.24 | J25: =Model!J35 -> 121385.5 | K25: =Model!K35 -> 125008.52 | L25: =Model!L35 -> 127066.69 | M25: =Model!M35 -> 129460.08 | N25: =Model!N35 -> 132016.44
B26: Depreciation 1 | I26: =-Model!I22 -> 11002.514 | J26: =-Model!J22 -> 13123.943 | K26: =-Model!K22 -> 15338.229 | L26: =-Model!L22 -> 17645.371 | M26: =-Model!M22 -> 20052.514 | N26: =-Model!N22 -> 18500 | Z26: NET INCOME METHOD
B27: Deferred Tax 2 | I27: =-Model!I32 -> 398.29102 | J27: =-Model!J32 -> 475.08673 | K27: =-Model!K32 -> 555.24387 | L27: =-Model!L32 -> 638.76245 | M27: =-Model!M32 -> 725.90102 | N27: =-Model!N32 -> 0 | Z27: Net Income
B28: After-Tax Net Non-Operating Expense | C28: ` | I28: =((-Model!I27)-Model!I28-Model!I26)*(1-DCF!$G$11) -> 1722.4676 | J28: =((-Model!J27)-Model!J28-Model!J26)*(1-DCF!$G$11) -> 1108.0526 | K28: =((-Model!K27)-Model!K28-Model!K26)*(1-DCF!$G$11) -> 240.0159 | L28: =((-Model!L27)-Model!L28-Model!L26)*(1-DCF!$G$11) -> -787.66011 | M28: =((-Model!M27)-Model!M28-Model!M26)*(1-DCF!$G$11) -> -1965.0077 | N28: =((-Model!N27)-Model!N28-Model!N26)*(1-DCF!$G$11) -> -2182.0279 | Z28: Depreciation 1
B29: Capital Expenditure | I29: =I19 -> -14500 | J29: =J19 -> -15200 | K29: =K19 -> -15800 | L29: =L19 -> -16500 | M29: =M19 -> -17200 | N29: =N19 -> -18500 | Z29: Deferred Tax 2
B30: Change in Working Capital | I30: =I20 -> -2462.6195 | J30: =J20 -> 280.44197 | K30: =K20 -> 393.17628 | L30: =L20 -> 788.19707 | M30: =M20 -> 749.31049 | N30: =N20 -> 337.88612 | Z30: Interest Expense
B31: Unlevered Free Cash Flow | I31: =SUM(I25:I30) -> 112360.89 | J31: =SUM(J25:J30) -> 121173.02 | K31: =SUM(K25:K30) -> 125735.19 | L31: =SUM(L25:L30) -> 128851.36 | M31: =SUM(M25:M30) -> 131822.8 | N31: =SUM(N25:N30) -> 130172.3 | Z31: Less: Interest Income
Z32: Plus: Other Expense
Z33: Tax Shield From Interest
B34: Two UFCF Methods Different? | I34: =IF(ROUND(I21-I31,1)=0,0,1) -> 0 | J34: =IF(ROUND(J21-J31,1)=0,0,1) -> 0 | K34: =IF(ROUND(K21-K31,1)=0,0,1) -> 0 | L34: =IF(ROUND(L21-L31,1)=0,0,1) -> 0 | M34: =IF(ROUND(M21-M31,1)=0,0,1) -> 0 | N34: =IF(ROUND(N21-N31,1)=0,0,1) -> 0 | Z34: Capital Expenditure
Z35: Change in Working Capital
Z36: Unlevered Free Cash Flow
N37: Capital expenditure has been set equal to depreciation in the terminal year.
N38: This schedule assumes no deferred taxes in the terminal year.
B42: Discounted Cash Flow Schedule: Perpetuity Method
B44: All figures in USD millions unless stated
B45: =B6 -> Model Running: Base Case Drivers | H45: Valuation | I45: Discrete Forecast | N45: Term
H46: (YY-MM-DD) | I46: (YY-MM-DD) | J46: (YY-MM-DD) | K46: (YY-MM-DD) | L46: (YY-MM-DD) | M46: (YY-MM-DD) | N46: (YY-MM-DD)
B47: Terminal Growth | C47: =Inputs!F116 -> 0.025 | F47: Fiscal Year End | H47: =Inputs!F103 -> 46121 | I47: =Inputs!F105 -> 46291 | J47: =EDATE(I47,12) -> 46656 | K47: =EDATE(J47,12) -> 47022 | L47: =EDATE(K47,12) -> 47387 | M47: =EDATE(L47,12) -> 47752 | N47: =EDATE(M47,12) -> 48117
B48: WACC | C48: =Inputs!L76 -> 0.08564409 | F48: Cash Flow Timing | H48: =H47 -> 46121 | I48: =Inputs!F104 -> 46291 | J48: =EDATE(I48,12) -> 46656 | K48: =EDATE(J48,12) -> 47022 | L48: =EDATE(K48,12) -> 47387 | M48: =EDATE(L48,12) -> 47752 | N48: =EDATE(M48,12) -> 48117
B50: Unlevered Free Cash Flow | H50: 0 | I50: =I$31 -> 112360.89 | J50: =J$31 -> 121173.02 | K50: =K$31 -> 125735.19 | L50: =L$31 -> 128851.36 | M50: =M$31 -> 131822.8 | N50: =N$31 -> 130172.3
B53: UNADJUSTED CASH FLOW
B54: Discrete Forecast | H54: 0 | I54: =I50 -> 112360.89 | J54: =J50 -> 121173.02 | K54: =K50 -> 125735.19 | L54: =L50 -> 128851.36 | M54: =M50 -> 131822.8
B55: Terminal Value | H55: 0 | I55: 0 | J55: 0 | K55: 0 | L55: 0 | M55: =N50/(C48-C47) -> 2146496
B56: Total Cash Flow | H56: =SUM(H54:H55) -> 0 | I56: =SUM(I54:I55) -> 112360.89 | J56: =SUM(J54:J55) -> 121173.02 | K56: =SUM(K54:K55) -> 125735.19 | L56: =SUM(L54:L55) -> 128851.36 | M56: =SUM(M54:M55) -> 2278318.8
...
